Workbook

Sheet Medicinal Purchase
A1: Name | B1: Date | C1: Expiry | D1: Qty | E1: Rate | F1: Amount | G1: Supplier | H1: Category | I1: Shelf Life left after purchase
A2: HEPDOZ-DS-SYP | B2: 45797 | C2: 46600 | D2: 10 | E2: 35 | F2: =D2*E2 -> 350 | G2: Chintpurni | H2: =VLOOKUP(A2,'Medicinal details'!A2:C11,3,FALSE) -> Digestive aids | I2: =C2-B2 -> 803
A3: NEO-LEEKUF TAB | B3: 45797 | C3: 46235 | D3: 20 | E3: 8.4 | F3: =D3*E3 -> 168 | G3: Chintpurni | H3: =VLOOKUP(A3,'Medicinal details'!A3:C11,3,FALSE) -> Cold and Flu remedies | I3: =C3-B3 -> 438
A4: HEPDOZ-DS-SYP | B4: 45797 | C4: 46600 | D4: 20 | E4: 35 | F4: =D4*E4 -> 700 | G4: Chintpurni | H4: =VLOOKUP(A4,'Medicinal details'!A2:C11,3,FALSE) -> Digestive aids | I4: =C4-B4 -> 803
A5: Limtonezyme DS SYP | B5: 45797 | C5: 46600 | D5: 6 | E5: 36 | F5: =D5*E5 -> 216 | G5: Chintpurni | H5: =VLOOKUP(A5,'Medicinal details'!A3:C11,3,FALSE) -> Digestive aids | I5: =C5-B5 -> 803
A6: ELDERVIT-SG CAP | B6: 45797 | C6: 46204 | D6: 20 | E6: 9.5 | F6: =D6*E6 -> 190 | G6: Chintpurni | H6: =VLOOKUP(A6,'Medicinal details'!A5:C11,3,FALSE) -> Supplements and Vitamins | I6: =C6-B6 -> 407
A7: NEUROLLEN-PLUS CAP | B7: 45802 | C7: 46174 | D7: 20 | E7: 33.93 | F7: =D7*E7 -> 678.6 | G7: Ashoka | H7: =VLOOKUP(A7,'Medicinal details'!A5:C11,3,FALSE) -> Supplements and Vitamins | I7: =C7-B7 -> 372
A8: LET LC TAB | B8: 45802 | C8: 45992 | D8: 2 | E8: 220 | F8: =D8*E8 -> 440 | G8: Rampal | H8: =VLOOKUP(A8,'Medicinal details'!A7:C11,3,FALSE) -> Cold and Flu remedies | I8: =C8-B8 -> 190
A9: HEPDOZ-DS-SYP | B9: 45804 | C9: 46600 | D9: 10 | E9: 35 | F9: =D9*E9 -> 350 | G9: Chintpurni | H9: =VLOOKUP(A9,'Medicinal details'!$A$1:$C$11,3,FALSE) -> Digestive aids | I9: =C9-B9 -> 796
A10: Limtonezyme DS SYP | B10: 45804 | C10: 46600 | D10: 6 | E10: 36 | F10: =D10*E10 -> 216 | G10: Chintpurni | H10: =VLOOKUP(A10,'Medicinal details'!$A$1:$C$11,3,FALSE) -> Digestive aids | I10: =C10-B10 -> 796
A11: NIMBRA PLUS DL | B11: 45804 | C11: 46054 | D11: 60 | E11: 5 | F11: =D11*E11 -> 300 | G11: Chintpurni | H11: =VLOOKUP(A11,'Medicinal details'!$A$1:$C$11,3,FALSE) -> Pain reliever | I11: =C11-B11 -> 250
A12: RABISUN-DSR CAP | B12: 45804 | C12: 46296 | D12: 40 | E12: 9.25 | F12: =D12*E12 -> 370 | G12: Chintpurni | H12: =VLOOKUP(A12,'Medicinal details'!$A$1:$C$11,3,FALSE) -> Antibiotics | I12: =C12-B12 -> 492
A13: NEO-LEEKUF TAB | B13: 45804 | C13: 46235 | D13: 10 | E13: 8.4 | F13: =D13*E13 -> 84 | G13: Chintpurni | H13: =VLOOKUP(A13,'Medicinal details'!$A$1:$C$11,3,FALSE) -> Cold and Flu remedies | I13: =C13-B13 -> 431
A14: NEUROLLEN-PLUS CAP | B14: 45807 | C14: 46174 | D14: 10 | E14: 33.93 | F14: =D14*E14 -> 339.3 | G14: Ashoka | H14: =VLOOKUP(A14,'Medicinal details'!$A$1:$C$11,3,FALSE) -> Supplements and Vitamins | I14: =C14-B14 -> 367
A15: LET LC TAB | B15: 45807 | C15: 46388 | D15: 1 | E15: 220 | F15: =D15*E15 -> 220 | G15: Rampal | H15: =VLOOKUP(A15,'Medicinal details'!$A$1:$C$11,3,FALSE) -> Cold and Flu remedies | I15: =C15-B15 -> 581
A16: AUGCLAV-LB | B16: 45814 | C16: 45931 | D16: 20 | E16: 40.18 | F16: =D16*E16 -> 803.6 | G16: Ashoka | H16: =VLOOKUP(A16,'Medicinal details'!$A$1:$C$11,3,FALSE) -> Antibiotics | I16: =C16-B16 -> 117
A17: NEUROLLEN-PLUS CAP | B17: 45814 | C17: 46174 | D17: 20 | E17: 33.93 | F17: =D17*E17 -> 678.6 | G17: Ashoka | H17: =VLOOKUP(A17,'Medicinal details'!$A$1:$C$11,3,FALSE) -> Supplements and Vitamins | I17: =C17-B17 -> 360
A18: HEPDOZ-DS-SYP | B18: 45822 | C18: 46600 | D18: 10 | E18: 35 | F18: =D18*E18 -> 350 | G18: Chintpurni | H18: =VLOOKUP(A18,'Medicinal details'!$A$1:$C$11,3,FALSE) -> Digestive aids | I18: =C18-B18 -> 778
A19: RABISUN-DSR CAP | B19: 45822 | C19: 46296 | D19: 40 | E19: 9.25 | F19: =D19*E19 -> 370 | G19: Chintpurni | H19: =VLOOKUP(A19,'Medicinal details'!$A$1:$C$11,3,FALSE) -> Antibiotics | I19: =C19-B19 -> 474
A20: NIMBRA PLUS DL | B20: 45822 | C20: 46054 | D20: 30 | E20: 5 | F20: =D20*E20 -> 150 | G20: Chintpurni | H20: =VLOOKUP(A20,'Medicinal details'!$A$1:$C$11,3,FALSE) -> Pain reliever | I20: =C20-B20 -> 232
... A25: HEPDOZ-DS-SYP | B25: 45824 | C25: 46600 | D25: 6 | E25: 35 | F25: =D25*E25 -> 210 | G25: Chintpurni | H25: =VLOOKUP(A25,'Medicinal details'!$A$1:$C$11,3,FALSE) -> Digestive aids | I25: =C25-B25 -> 776

Sheet Non-medicinal Sales
A2: Date | B2: Day | C2: Product Name | D2: Units Sold | E2: Selling Price | F2: Revenue | G2: Category | H2: Profit
A3: 45797 | B3: =TEXT(A3,"dddd") -> Tuesday | C3: Head and Shoulder 650ml | D3: 1 | E3: =VLOOKUP(C3,'Non-medicinal details'!$A$1:$E$12,4,FALSE) -> 520 | F3: =D3*E3 -> 520 | G3: =VLOOKUP(C3,'Non-medicinal details'!$A$1:$E$12,3,FALSE) -> Hair Care | H3: =F3-(VLOOKUP(C3,'Non-medicinal details'!$A$1:$E$12,5,FALSE)*D3) -> 20
A4: 45797 | B4: =TEXT(A4,"dddd") -> Tuesday | C4: Indulekha Hair Oil 100ml | D4: 0 | E4: =VLOOKUP(C4,'Non-medicinal details'!$A$1:$E$12,4,FALSE) -> 248 | F4: =D4*E4 -> 0 | G4: =VLOOKUP(C4,'Non-medicinal details'!$A$1:$E$12,3,FALSE) -> Hair Care | H4: =F4-(VLOOKUP(C4,'Non-medicinal details'!$A$1:$E$12,5,FALSE)*D4) -> 0
A5: 45797 | B5: =TEXT(A5,"dddd") -> Tuesday | C5: Listerine Mouthwash 250ml | D5: 0 | E5: =VLOOKUP(C5,'Non-medicinal details'!$A$1:$E$12,4,FALSE) -> 200 | F5: =D5*E5 -> 0 | G5: =VLOOKUP(C5,'Non-medicinal details'!$A$1:$E$12,3,FALSE) -> Oral Care | H5: =F5-(VLOOKUP(C5,'Non-medicinal details'!$A$1:$E$12,5,FALSE)*D5) -> 0
A6: 45797 | B6: =TEXT(A6,"dddd") -> Tuesday | C6: Toothpastes | D6: 1 | E6: =VLOOKUP(C6,'Non-medicinal details'!$A$1:$E$12,4,FALSE) -> 46 | F6: =D6*E6 -> 46 | G6: =VLOOKUP(C6,'Non-medicinal details'!$A$1:$E$12,3,FALSE) -> Oral Care | H6: =F6-(VLOOKUP(C6,'Non-medicinal details'!$A$1:$E$12,5,FALSE)*D6) -> 16
A7: 45797 | B7: =TEXT(A7,"dddd") -> Tuesday | C7: Vaseline 100ml | D7: 0 | E7: =VLOOKUP(C7,'Non-medicinal details'!$A$1:$E$12,4,FALSE) -> 95 | F7: =D7*E7 -> 0 | G7: =VLOOKUP(C7,'Non-medicinal details'!$A$1:$E$12,3,FALSE) -> Skin Care | H7: =F7-(VLOOKUP(C7,'Non-medicinal details'!$A$1:$E$12,5,FALSE)*D7) -> 0
A8: 45797 | B8: =TEXT(A8,"dddd") -> Tuesday | C8: Boroline 20g | D8: 0 | E8: =VLOOKUP(C8,'Non-medicinal details'!$A$1:$E$12,4,FALSE) -> 35 | F8: =D8*E8 -> 0 | G8: =VLOOKUP(C8,'Non-medicinal details'!$A$1:$E$12,3,FALSE) -> Skin Care | H8: =F8-(VLOOKUP(C8,'Non-medicinal details'!$A$1:$E$12,5,FALSE)*D8) -> 0
A9: 45797 | B9: =TEXT(A9,"dddd") -> Tuesday | C9: Pampers Diapers Pack | D9: 1 | E9: =VLOOKUP(C9,'Non-medicinal details'!$A$1:$E$12,4,FALSE) -> 60 | F9: =D9*E9 -> 60 | G9: =VLOOKUP(C9,'Non-medicinal details'!$A$1:$E$12,3,FALSE) -> Baby and Child Care | H9: =F9-(VLOOKUP(C9,'Non-medicinal details'!$A$1:$E$12,5,FALSE)*D9) -> 20
A10: 45797 | B10: =TEXT(A10,"dddd") -> Tuesday | C10: Johnson's Baby Powder 100g | D10: 1 | E10: =VLOOKUP(C10,'Non-medicinal details'!$A$1:$E$12,4,FALSE) -> 120 | F10: =D10*E10 -> 120 | G10: =VLOOKUP(C10,'Non-medicinal details'!$A$1:$E$12,3,FALSE) -> Baby and Child Care | H10: =F10-(VLOOKUP(C10,'Non-medicinal details'!$A$1:$E$12,5,FALSE)*D10) -> 10
A11: 45797 | B11: =TEXT(A11,"dddd") -> Tuesday | C11: Dettol Soap 100g | D11: 0 | E11: =VLOOKUP(C11,'Non-medicinal details'!$A$1:$E$12,4,FALSE) -> 50 | F11: =D11*E11 -> 0 | G11: =VLOOKUP(C11,'Non-medicinal details'!$A$1:$E$12,3,FALSE) -> Hygiene | H11: =F11-(VLOOKUP(C11,'Non-medicinal details'!$A$1:$E$12,5,FALSE)*D11) -> 0
A12: 45797 | B12: =TEXT(A12,"dddd") -> Tuesday | C12: Bournvita 550g | D12: 0 | E12: =VLOOKUP(C12,'Non-medicinal details'!$A$1:$E$12,4,FALSE) -> 250 | F12: =D12*E12 -> 0 | G12: =VLOOKUP(C12,'Non-medicinal details'!$A$1:$E$12,3,FALSE) -> Nutritional powders | H12: =F12-(VLOOKUP(C12,'Non-medicinal details'!$A$1:$E$12,5,FALSE)*D12) -> 0
A13: 45797 | B13: =TEXT(A13,"dddd") -> Tuesday | C13: Horlicks 500g | D13: 1 | E13: =VLOOKUP(C13,'Non-medicinal details'!$A$1:$E$12,4,FALSE) -> 249 | F13: =D13*E13 -> 249 | G13: =VLOOKUP(C13,'Non-medicinal details'!$A$1:$E$12,3,FALSE) -> Nutritional powders | H13: =F13-(VLOOKUP(C13,'Non-medicinal details'!$A$1:$E$12,5,FALSE)*D13) -> 49
A14: 45798 | B14: =TEXT(A14,"dddd") -> Wednesday | C14: Head and Shoulder 650ml | D14: 0 | E14: =VLOOKUP(C14,'Non-medicinal details'!$A$1:$E$12,4,FALSE) -> 520 | F14: =D14*E14 -> 0 | G14: =VLOOKUP(C14,'Non-medicinal details'!$A$1:$E$12,3,FALSE) -> Hair Care | H14: =F14-(VLOOKUP(C14,'Non-medicinal details'!$A$1:$E$12,5,FALSE)*D14) -> 0
... A332: 45826 | B332: =TEXT(A332,"dddd") -> Wednesday | C332: Horlicks 500g | D332: 0 | E332: =VLOOKUP(C332,'Non-medicinal details'!$A$1:$E$12,4,FALSE) -> 249 | F332: =D332*E332 -> 0 | G332: =VLOOKUP(C332,'Non-medicinal details'!$A$1:$E$12,3,FALSE) -> Nutritional powders | H332: =F332-(VLOOKUP(C332,'Non-medicinal details'!$A$1:$E$12,5,FALSE)*D332) -> 0

Sheet Medicinal details
A1: Name | B1: Type | C1: Category
A2: Hepdoz-ds-SYP | B2: Medicinal | C2: Digestive aids
A3: NEO-LEEKUF TAB | B3: Medicinal | C3: Cold and Flu remedies
A4: Limtonezyme DS SYP | B4: Medicinal | C4: Digestive aids
A5: ELDERVIT-SG CAP | B5: Medicinal | C5: Supplements and Vitamins
A6: NEUROLLEN-PLUS CAP | B6: Medicinal | C6: Supplements and Vitamins
A7: LET LC TAB | B7: Medicinal | C7: Cold and Flu remedies
A8: NIMBRA PLUS DL | B8: Medicinal | C8: Pain reliever
A9: RABISUN-DSR CAP | B9: Medicinal | C9: Antibiotics
A10: AUGCLAV-LB | B10: Medicinal | C10: Antibiotics
A11: NIMBRA PLUS G TAB | B11: Medicinal | C11: Pain reliever

Sheet Non-medicinal details
A1: Name | B1: Type | C1: Category | D1: Avg Selling Price | E1: Cost
A2: Head and Shoulder 650ml | B2: Non-Medicinal | C2: Hair Care | D2: 520 | E2: 500
A3: Indulekha Hair Oil 100ml | B3: Non-Medicinal | C3: Hair Care | D3: 248 | E3: 160
A4: Listerine Mouthwash 250ml | B4: Non-Medicinal | C4: Oral Care | D4: 200 | E4: 180
A5: Toothpastes | B5: Non-Medicinal | C5: Oral Care | D5: 46 | E5: 30
A6: Vaseline 100ml | B6: Non-Medicinal | C6: Skin Care | D6: 95 | E6: 85
A7: Boroline 20g | B7: Non-Medicinal | C7: Skin Care | D7: 35 | E7: 28
A8: Pampers Diapers Pack | B8: Non-Medicinal | C8: Baby and Child Care | D8: 60 | E8: 40
A9: Johnson's Baby Powder 100g | B9: Non-Medicinal | C9: Baby and Child Care | D9: 120 | E9: 110
A10: Dettol Soap 100g | B10: Non-Medicinal | C10: Hygiene | D10: 50 | E10: 38
A11: Bournvita 550g | B11: Non-Medicinal | C11: Nutritional powders | D11: 250 | E11: 210
A12: Horlicks 500g | B12: Non-Medicinal | C12: Nutritional powders | D12: 249 | E12: 200

Sheet Non med analysis
A3: Row Labels | B3: Sum of Revenue | G3: Row Labels | H3: Sum of Revenue | I3: Cumulative Revenue | J3: Percentage | L3: Category | M3: Profit | R3: Date | S3: Profit | V3: Day | W3: Profit
A4: Baby and Child Care | B4: 2760 | G4: Head and Shoulder 650ml | H4: =VLOOKUP(G4,$A$15:$B$25,2,FALSE) -> 4680 | I4: =H4 -> 4680 | J4: =(I4/$I$14)*100 -> 23.055323 | L4: Nutritional powders | M4: 1117 | R4: 20-May | S4: 115 | V4: Sunday | W4: 439
A5: Hair Care | B5: 6912 | G5: Horlicks 500g | H5: =VLOOKUP(G5,$A$15:$B$25,2,FALSE) -> 3237 | I5: =I4+H5 -> 7917 | J5: =(I5/$I$14)*100 -> 39.001921 | L5: Hair Care | M5: 972 | R5: 21-May | S5: 20 | V5: Monday | W5: 944
A6: Hygiene | B6: 1450 | G6: Bournvita 550g | H6: =VLOOKUP(G6,$A$15:$B$25,2,FALSE) -> 3000 | I6: =I5+H6 -> 10917 | J6: =(I6/$I$14)*100 -> 53.780974 | L6: Baby and Child Care | M6: 620 | R6: 22-May | S6: 112 | V6: Tuesday | W6: 638
A7: Nutritional powders | B7: 6237 | G7: Indulekha Hair Oil 100ml | H7: =VLOOKUP(G7,$A$15:$B$25,2,FALSE) -> 2232 | I7: =I6+H7 -> 13149 | J7: =(I7/$I$14)*100 -> 64.77659 | L7: Oral Care | M7: 520 | R7: 23-May | S7: 52 | V7: Wednesday | W7: 340
A8: Oral Care | B8: 1780 | G8: Pampers Diapers Pack | H8: =VLOOKUP(G8,$A$15:$B$25,2,FALSE) -> 1560 | I8: =I7+H8 -> 14709 | J8: =(I8/$I$14)*100 -> 72.461698 | L8: Hygiene | M8: 348 | R8: 24-May | S8: 27 | V8: Thursday | W8: 646
A9: Skin Care | B9: 1160 | G9: Dettol Soap 100g | H9: =VLOOKUP(G9,$A$15:$B$25,2,FALSE) -> 1450 | I9: =I8+H9 -> 16159 | J9: =(I9/$I$14)*100 -> 79.604907 | L9: Skin Care | M9: 142 | R9: 25-May | S9: 91 | V9: Friday | W9: 456
A10: Grand Total | B10: 20299 | G10: Toothpastes | H10: =VLOOKUP(G10,$A$15:$B$25,2,FALSE) -> 1380 | I10: =I9+H10 -> 17539 | J10: =(I10/$I$14)*100 -> 86.403271 | R10: 26-May | S10: 171 | V10: Saturday | W10: 256
G11: Johnson's Baby Powder 100g | H11: =VLOOKUP(G11,$A$15:$B$25,2,FALSE) -> 1200 | I11: =I10+H11 -> 18739 | J11: =(I11/$I$14)*100 -> 92.314892 | R11: 27-May | S11: 109
G12: Vaseline 100ml | H12: =VLOOKUP(G12,$A$15:$B$25,2,FALSE) -> 950 | I12: =I11+H12 -> 19689 | J12: =(I12/$I$14)*100 -> 96.994926 | R12: 28-May | S12: 129
G13: Listerine Mouthwash 250ml | H13: =VLOOKUP(G13,$A$15:$B$25,2,FALSE) -> 400 | I13: =I12+H13 -> 20089 | J13: =(I13/$I$14)*100 -> 98.965466 | R13: 29-May | S13: 188
A14: Row Labels | B14: Sum of Revenue | G14: Boroline 20g | H14: =VLOOKUP(G14,$A$15:$B$25,2,FALSE) -> 210 | I14: =I13+H14 -> 20299 | J14: =(I14/$I$14)*100 -> 100 | R14: 30-May | S14: 96
A15: Boroline 20g | B15: 210 | R15: 31-May | S15: 32
A16: Bournvita 550g | B16: 3000 | R16: 01-Jun | S16: 181
A17: Dettol Soap 100g | B17: 1450 | R17: 02-Jun | S17: 327
A18: Head and Shoulder 650ml | B18: 4680 | R18: 03-Jun | S18: 74
A19: Horlicks 500g | B19: 3237 | G19: Category | H19: Sum of revenue | I19: Sum of units sols | R19: 04-Jun | S19: 112
A20: Indulekha Hair Oil 100ml | B20: 2232 | G20: Hair Care | H20: 6912 | I20: 18 | R20: 05-Jun | S20: 89
A21: Johnson's Baby Powder 100g | B21: 1200 | G21: Nutritional powders | H21: 6237 | I21: 25 | R21: 06-Jun | S21: 120
A22: Listerine Mouthwash 250ml | B22: 400 | G22: Baby and Child Care | H22: 2760 | I22: 36 | R22: 07-Jun | S22: 73
A23: Pampers Diapers Pack | B23: 1560 | G23: Oral Care | H23: 1780 | I23: 32 | R23: 08-Jun | S23: 98
A24: Toothpastes | B24: 1380 | G24: Hygiene | H24: 1450 | I24: 29 | R24: 09-Jun | S24: 217
A25: Vaseline 100ml | B25: 950 | G25: Skin Care | H25: 1160 | I25: 16 | R25: 10-Jun | S25: 82
A26: Grand Total | B26: 20299 | R26: 11-Jun | S26: 19
R27: 12-Jun | S27: 257
G28: Date | H28: Units Sold | R28: 13-Jun | S28: 188
G29: 20-May | H29: 5 | R29: 14-Jun | S29: 124
G30: 21-May | H30: 1 | J30: Product | K30: Revenue | L30: Cumulative revenue | M30: Percentage | R30: 15-Jun | S30: 69
G31: 22-May | H31: 5 | J31: Head and Shoulder 650ml | K31: 4680 | L31: =K31 -> 4680 | M31: =L31/L41 -> 0.23055323 | R31: 16-Jun | S31: 229
G32: 23-May | H32: 2 | J32: Horlicks 500g | K32: 3237 | L32: =L31+K32 -> 7917 | M32: =L32/20299 -> 0.39001921 | R32: 17-Jun | S32: 258
G33: 24-May | H33: 4 | J33: Bournvita 550g | K33: 3000 | L33: =L32+K33 -> 10917 | M33: =L33/20299 -> 0.53780974 | R33: 18-Jun | S33: 60
G34: 25-May | H34: 7 | J34: Indulekha Hair Oil 100ml | K34: 2232 | L34: =L33+K34 -> 13149 | M34: =L34/20299 -> 0.6477659
G35: 26-May | H35: 7 | J35: Pampers Diapers Pack | K35: 1560 | L35: =L34+K35 -> 14709 | M35: =L35/20299 -> 0.72461698
G36: 27-May | H36: 6 | J36: Dettol Soap 100g | K36: 1450 | L36: =L35+K36 -> 16159 | M36: =L36/20299 -> 0.79604907
G37: 28-May | H37: 10 | J37: Toothpastes | K37: 1380 | L37: =L36+K37 -> 17539 | M37: =L37/20299 -> 0.86403271
G38: 29-May | H38: 7 | J38: Johnson's Baby Powder 100g | K38: 1200 | L38: =L37+K38 -> 18739 | M38: =L38/20299 -> 0.92314892
G39: 30-May | H39: 4 | J39: Vaseline 100ml | K39: 950 | L39: =L38+K39 -> 19689 | M39: =L39/20299 -> 0.96994926
G40: 31-May | H40: 1 | J40: Listerine Mouthwash 250ml | K40: 400 | L40: =L39+K40 -> 20089 | M40: =L40/20299 -> 0.98965466
G41: 01-Jun | H41: 9 | J41: Boroline 20g | K41: 210 | L41: =L40+K41 -> 20299 | M41: =L41/20299 -> 1
G42: 02-Jun | H42: 9
...

Sheet Medicinal Analysis
D4: Supplier | E4: Sum of amount spent
D5: Chintpurni | E5: 5020
D6: Ashoka | E6: 2500.1
D7: Rampal | E7: 660
A8: Row Labels | B8: Sum of Amount
A9: Antibiotics | B9: 1913.6
A10: Cold and Flu remedies | B10: 1248
A11: Digestive aids | B11: 2392
A12: Pain reliever | B12: 550
A13: Supplements and Vitamins | B13: 2076.5
A14: Grand Total | B14: 8180.1
D16: Supplier | E16: Antibiotics | F16: Cold and Flu | G16: Digestive Aids | H16: Pain reliever | I16: Supplements and vitamins
D17: Ashoka | E17: 803.6 | I17: 1696.5
D18: Chintpurni | E18: 1110 | F18: 588 | G18: 2392 | H18: 550 | I18: 380
D19: Rampal | F19: 660
A30: Category | B30: Average shelf life left | D30: Supplier | E30: Frequency of purchase
A31: Digestive aids | B31: 793.57143 | D31: Chintpurni | E31: 18
A32: Cold and Flu remedies | B32: 410.2 | D32: Ashoka | E32: 4
A33: Antibiotics | B33: 388.75 | D33: Rampal | E33: 2
A34: Supplements and Vitamins | B34: 377.2
A35: Pain reliever | B35: 308
D36: Category | E36: Total amount spent
D37: Antibiotics | E37: 1913.6
D38: Cold and Flu remedies | E38: 1248
D39: Digestive aids | E39: 2392
D40: Pain reliever | E40: 550
D41: Supplements and Vitamins | E41: 2076.5
D44: Date | E44: Total Amount spent
D45: 20-May | E45: 1624
D46: 25-May | E46: 1118.6
D47: 27-May | E47: 1320
D48: 30-May | E48: 559.3
D49: 06-Jun | E49: 1482.2
D50: 14-Jun | E50: 870
D51: 16-Jun | E51: 1206
D54: For amount spent
D55: Index | E55: Value
D56: Mean | E56: =AVERAGE(E45:E51) -> 1168.5857
D57: Min | E57: =MIN(E45:E51) -> 559.3
D58: Max | E58: =MAX(E45:E51) -> 1624
...
